Traceback (most recent call last):
  File "/Users/filipacalado/opt/anaconda3/lib/python3.7/site-packages/jupyter_cache/executors/utils.py", line 56, in single_nb_execution
    record_timing=False,
  File "/Users/filipacalado/opt/anaconda3/lib/python3.7/site-packages/nbclient/client.py", line 1204, in execute
    return NotebookClient(nb=nb, resources=resources, km=km, **kwargs).execute()
  File "/Users/filipacalado/opt/anaconda3/lib/python3.7/site-packages/nbclient/util.py", line 84, in wrapped
    return just_run(coro(*args, **kwargs))
  File "/Users/filipacalado/opt/anaconda3/lib/python3.7/site-packages/nbclient/util.py", line 62, in just_run
    return loop.run_until_complete(coro)
  File "/Users/filipacalado/opt/anaconda3/lib/python3.7/asyncio/base_events.py", line 587, in run_until_complete
    return future.result()
  File "/Users/filipacalado/opt/anaconda3/lib/python3.7/site-packages/nbclient/client.py", line 664, in async_execute
    cell, index, execution_count=self.code_cells_executed + 1
  File "/Users/filipacalado/opt/anaconda3/lib/python3.7/site-packages/nbclient/client.py", line 965, in async_execute_cell
    await self._check_raise_for_error(cell, cell_index, exec_reply)
  File "/Users/filipacalado/opt/anaconda3/lib/python3.7/site-packages/nbclient/client.py", line 862, in _check_raise_for_error
    raise CellExecutionError.from_cell_and_msg(cell, exec_reply_content)
nbclient.exceptions.CellExecutionError: An error occurred while executing the following cell:
------------------
# running the "clean" function on the text "orlando"

orl = clean(orlando)
------------------

[0;31m---------------------------------------------------------------------------[0m
[0;31mNameError[0m                                 Traceback (most recent call last)
[0;32m<ipython-input-5-73ce5fb15cd5>[0m in [0;36m<module>[0;34m[0m
[1;32m      1[0m [0;31m# running the "clean" function on the text "orlando"[0m[0;34m[0m[0;34m[0m[0;34m[0m[0m
[1;32m      2[0m [0;34m[0m[0m
[0;32m----> 3[0;31m [0morl[0m [0;34m=[0m [0mclean[0m[0;34m([0m[0morlando[0m[0;34m)[0m[0;34m[0m[0;34m[0m[0m
[0m
[0;32m<ipython-input-3-cd8afc8ea239>[0m in [0;36mclean[0;34m(tokens)[0m
[1;32m      1[0m [0;32mdef[0m [0mclean[0m[0;34m([0m[0mtokens[0m[0;34m)[0m[0;34m:[0m[0;34m[0m[0;34m[0m[0m
[1;32m      2[0m     [0;31m# loads and tokenizes the text[0m[0;34m[0m[0;34m[0m[0;34m[0m[0m
[0;32m----> 3[0;31m     [0mopen_url[0m [0;34m=[0m [0murlopen[0m[0;34m([0m[0murl[0m[0;34m)[0m[0;34m[0m[0;34m[0m[0m
[0m[1;32m      4[0m     [0mread_text[0m [0;34m=[0m [0mopen_url[0m[0;34m.[0m[0mread[0m[0;34m([0m[0;34m)[0m[0;34m[0m[0;34m[0m[0m
[1;32m      5[0m     [0mdecoded_text[0m [0;34m=[0m [0mread_text[0m[0;34m.[0m[0mdecode[0m[0;34m([0m[0;34m)[0m[0;34m[0m[0;34m[0m[0m

[0;31mNameError[0m: name 'url' is not defined
NameError: name 'url' is not defined

