Traceback (most recent call last):
  File "/Users/filipacalado/opt/anaconda3/lib/python3.7/site-packages/jupyter_cache/executors/utils.py", line 56, in single_nb_execution
    record_timing=False,
  File "/Users/filipacalado/opt/anaconda3/lib/python3.7/site-packages/nbclient/client.py", line 1204, in execute
    return NotebookClient(nb=nb, resources=resources, km=km, **kwargs).execute()
  File "/Users/filipacalado/opt/anaconda3/lib/python3.7/site-packages/nbclient/util.py", line 84, in wrapped
    return just_run(coro(*args, **kwargs))
  File "/Users/filipacalado/opt/anaconda3/lib/python3.7/site-packages/nbclient/util.py", line 62, in just_run
    return loop.run_until_complete(coro)
  File "/Users/filipacalado/opt/anaconda3/lib/python3.7/asyncio/base_events.py", line 587, in run_until_complete
    return future.result()
  File "/Users/filipacalado/opt/anaconda3/lib/python3.7/site-packages/nbclient/client.py", line 664, in async_execute
    cell, index, execution_count=self.code_cells_executed + 1
  File "/Users/filipacalado/opt/anaconda3/lib/python3.7/site-packages/nbclient/client.py", line 965, in async_execute_cell
    await self._check_raise_for_error(cell, cell_index, exec_reply)
  File "/Users/filipacalado/opt/anaconda3/lib/python3.7/site-packages/nbclient/client.py", line 862, in _check_raise_for_error
    raise CellExecutionError.from_cell_and_msg(cell, exec_reply_content)
nbclient.exceptions.CellExecutionError: An error occurred while executing the following cell:
------------------
# the second one is bloom, read more here: https://huggingface.co/bigscience/bloom-560m 
bloom = pipeline('text-generation', model='bigscience/bloom-560m')
------------------

[0;31m---------------------------------------------------------------------------[0m
[0;31mValueError[0m                                Traceback (most recent call last)
[0;32m<ipython-input-16-ac0acd268046>[0m in [0;36m<module>[0;34m[0m
[1;32m      1[0m [0;31m# the second one is bloom, read more here: https://huggingface.co/bigscience/bloom-560m[0m[0;34m[0m[0;34m[0m[0;34m[0m[0m
[0;32m----> 2[0;31m [0mbloom[0m [0;34m=[0m [0mpipeline[0m[0;34m([0m[0;34m'text-generation'[0m[0;34m,[0m [0mmodel[0m[0;34m=[0m[0;34m'bigscience/bloom-560m'[0m[0;34m)[0m[0;34m[0m[0;34m[0m[0m
[0m
[0;32m~/opt/anaconda3/lib/python3.7/site-packages/transformers/pipelines/__init__.py[0m in [0;36mpipeline[0;34m(task, model, config, tokenizer, feature_extractor, framework, revision, use_fast, use_auth_token, device, device_map, torch_dtype, trust_remote_code, model_kwargs, pipeline_class, **kwargs)[0m
[1;32m    716[0m         [0mtask[0m[0;34m=[0m[0mtask[0m[0;34m,[0m[0;34m[0m[0;34m[0m[0m
[1;32m    717[0m         [0;34m**[0m[0mhub_kwargs[0m[0;34m,[0m[0;34m[0m[0;34m[0m[0m
[0;32m--> 718[0;31m         [0;34m**[0m[0mmodel_kwargs[0m[0;34m,[0m[0;34m[0m[0;34m[0m[0m
[0m[1;32m    719[0m     )
[1;32m    720[0m [0;34m[0m[0m

[0;32m~/opt/anaconda3/lib/python3.7/site-packages/transformers/pipelines/base.py[0m in [0;36minfer_framework_load_model[0;34m(model, config, model_classes, task, framework, **model_kwargs)[0m
[1;32m    264[0m [0;34m[0m[0m
[1;32m    265[0m         [0;32mif[0m [0misinstance[0m[0;34m([0m[0mmodel[0m[0;34m,[0m [0mstr[0m[0;34m)[0m[0;34m:[0m[0;34m[0m[0;34m[0m[0m
[0;32m--> 266[0;31m             [0;32mraise[0m [0mValueError[0m[0;34m([0m[0;34mf"Could not load model {model} with any of the following classes: {class_tuple}."[0m[0;34m)[0m[0;34m[0m[0;34m[0m[0m
[0m[1;32m    267[0m [0;34m[0m[0m
[1;32m    268[0m     [0mframework[0m [0;34m=[0m [0;34m"tf"[0m [0;32mif[0m [0mmodel[0m[0;34m.[0m[0m__class__[0m[0;34m.[0m[0m__name__[0m[0;34m.[0m[0mstartswith[0m[0;34m([0m[0;34m"TF"[0m[0;34m)[0m [0;32melse[0m [0;34m"pt"[0m[0;34m[0m[0;34m[0m[0m

[0;31mValueError[0m: Could not load model bigscience/bloom-560m with any of the following classes: (<class 'transformers.models.auto.modeling_tf_auto.TFAutoModelForCausalLM'>,).
ValueError: Could not load model bigscience/bloom-560m with any of the following classes: (<class 'transformers.models.auto.modeling_tf_auto.TFAutoModelForCausalLM'>,).

