Traceback (most recent call last):
  File "/Users/caladof/anaconda3/lib/python3.11/site-packages/jupyter_cache/executors/utils.py", line 58, in single_nb_execution
    executenb(
  File "/Users/caladof/anaconda3/lib/python3.11/site-packages/nbclient/client.py", line 1204, in execute
    return NotebookClient(nb=nb, resources=resources, km=km, **kwargs).execute()
           ^^^^^^^^^^^^^^^^^^^^^^^^^^^^^^^^^^^^^^^^^^^^^^^^^^^^^^^^^^^^^^^^^^^^^
  File "/Users/caladof/anaconda3/lib/python3.11/site-packages/nbclient/util.py", line 84, in wrapped
    return just_run(coro(*args, **kwargs))
           ^^^^^^^^^^^^^^^^^^^^^^^^^^^^^^^
  File "/Users/caladof/anaconda3/lib/python3.11/site-packages/nbclient/util.py", line 62, in just_run
    return loop.run_until_complete(coro)
           ^^^^^^^^^^^^^^^^^^^^^^^^^^^^^
  File "/Users/caladof/anaconda3/lib/python3.11/asyncio/base_events.py", line 650, in run_until_complete
    return future.result()
           ^^^^^^^^^^^^^^^
  File "/Users/caladof/anaconda3/lib/python3.11/contextlib.py", line 222, in __aexit__
    await self.gen.athrow(typ, value, traceback)
  File "/Users/caladof/anaconda3/lib/python3.11/site-packages/nbclient/client.py", line 608, in async_setup_kernel
    yield
  File "/Users/caladof/anaconda3/lib/python3.11/site-packages/nbclient/client.py", line 663, in async_execute
    await self.async_execute_cell(
  File "/Users/caladof/anaconda3/lib/python3.11/site-packages/nbclient/client.py", line 965, in async_execute_cell
    await self._check_raise_for_error(cell, cell_index, exec_reply)
  File "/Users/caladof/anaconda3/lib/python3.11/site-packages/nbclient/client.py", line 862, in _check_raise_for_error
    raise CellExecutionError.from_cell_and_msg(cell, exec_reply_content)
nbclient.exceptions.CellExecutionError: An error occurred while executing the following cell:
------------------
woman_vector = model.wv['man'] 
------------------

[0;31m---------------------------------------------------------------------------[0m
[0;31mKeyError[0m                                  Traceback (most recent call last)
Cell [0;32mIn[3], line 1[0m
[0;32m----> 1[0m woman_vector [38;5;241m=[39m model[38;5;241m.[39mwv[[38;5;124m'[39m[38;5;124mman[39m[38;5;124m'[39m]

File [0;32m~/anaconda3/lib/python3.11/site-packages/gensim/models/keyedvectors.py:403[0m, in [0;36mKeyedVectors.__getitem__[0;34m(self, key_or_keys)[0m
[1;32m    389[0m [38;5;250m[39m[38;5;124;03m"""Get vector representation of `key_or_keys`.[39;00m
[1;32m    390[0m 
[1;32m    391[0m [38;5;124;03mParameters[39;00m
[0;32m   (...)[0m
[1;32m    400[0m 
[1;32m    401[0m [38;5;124;03m"""[39;00m
[1;32m    402[0m [38;5;28;01mif[39;00m [38;5;28misinstance[39m(key_or_keys, _KEY_TYPES):
[0;32m--> 403[0m     [38;5;28;01mreturn[39;00m [38;5;28mself[39m[38;5;241m.[39mget_vector(key_or_keys)
[1;32m    405[0m [38;5;28;01mreturn[39;00m vstack([[38;5;28mself[39m[38;5;241m.[39mget_vector(key) [38;5;28;01mfor[39;00m key [38;5;129;01min[39;00m key_or_keys])

File [0;32m~/anaconda3/lib/python3.11/site-packages/gensim/models/keyedvectors.py:446[0m, in [0;36mKeyedVectors.get_vector[0;34m(self, key, norm)[0m
[1;32m    422[0m [38;5;28;01mdef[39;00m [38;5;21mget_vector[39m([38;5;28mself[39m, key, norm[38;5;241m=[39m[38;5;28;01mFalse[39;00m):
[1;32m    423[0m [38;5;250m    [39m[38;5;124;03m"""Get the key's vector, as a 1D numpy array.[39;00m
[1;32m    424[0m 
[1;32m    425[0m [38;5;124;03m    Parameters[39;00m
[0;32m   (...)[0m
[1;32m    444[0m 
[1;32m    445[0m [38;5;124;03m    """[39;00m
[0;32m--> 446[0m     index [38;5;241m=[39m [38;5;28mself[39m[38;5;241m.[39mget_index(key)
[1;32m    447[0m     [38;5;28;01mif[39;00m norm:
[1;32m    448[0m         [38;5;28mself[39m[38;5;241m.[39mfill_norms()

File [0;32m~/anaconda3/lib/python3.11/site-packages/gensim/models/keyedvectors.py:420[0m, in [0;36mKeyedVectors.get_index[0;34m(self, key, default)[0m
[1;32m    418[0m     [38;5;28;01mreturn[39;00m default
[1;32m    419[0m [38;5;28;01melse[39;00m:
[0;32m--> 420[0m     [38;5;28;01mraise[39;00m [38;5;167;01mKeyError[39;00m([38;5;124mf[39m[38;5;124m"[39m[38;5;124mKey [39m[38;5;124m'[39m[38;5;132;01m{[39;00mkey[38;5;132;01m}[39;00m[38;5;124m'[39m[38;5;124m not present[39m[38;5;124m"[39m)

[0;31mKeyError[0m: "Key 'man' not present"
KeyError: "Key 'man' not present"

