Traceback (most recent call last):
  File "/Users/filipacalado/opt/anaconda3/lib/python3.7/site-packages/jupyter_cache/executors/utils.py", line 56, in single_nb_execution
    record_timing=False,
  File "/Users/filipacalado/opt/anaconda3/lib/python3.7/site-packages/nbclient/client.py", line 1204, in execute
    return NotebookClient(nb=nb, resources=resources, km=km, **kwargs).execute()
  File "/Users/filipacalado/opt/anaconda3/lib/python3.7/site-packages/nbclient/util.py", line 84, in wrapped
    return just_run(coro(*args, **kwargs))
  File "/Users/filipacalado/opt/anaconda3/lib/python3.7/site-packages/nbclient/util.py", line 62, in just_run
    return loop.run_until_complete(coro)
  File "/Users/filipacalado/opt/anaconda3/lib/python3.7/asyncio/base_events.py", line 587, in run_until_complete
    return future.result()
  File "/Users/filipacalado/opt/anaconda3/lib/python3.7/site-packages/nbclient/client.py", line 664, in async_execute
    cell, index, execution_count=self.code_cells_executed + 1
  File "/Users/filipacalado/opt/anaconda3/lib/python3.7/site-packages/nbclient/client.py", line 965, in async_execute_cell
    await self._check_raise_for_error(cell, cell_index, exec_reply)
  File "/Users/filipacalado/opt/anaconda3/lib/python3.7/site-packages/nbclient/client.py", line 862, in _check_raise_for_error
    raise CellExecutionError.from_cell_and_msg(cell, exec_reply_content)
nbclient.exceptions.CellExecutionError: An error occurred while executing the following cell:
------------------
woman_vector = model.wv['man'] 
------------------

[0;31m---------------------------------------------------------------------------[0m
[0;31mKeyError[0m                                  Traceback (most recent call last)
[0;32m<ipython-input-3-ec1ba664252f>[0m in [0;36m<module>[0;34m[0m
[0;32m----> 1[0;31m [0mwoman_vector[0m [0;34m=[0m [0mmodel[0m[0;34m.[0m[0mwv[0m[0;34m[[0m[0;34m'man'[0m[0;34m][0m[0;34m[0m[0;34m[0m[0m
[0m
[0;32m~/opt/anaconda3/lib/python3.7/site-packages/gensim/models/keyedvectors.py[0m in [0;36m__getitem__[0;34m(self, key_or_keys)[0m
[1;32m    402[0m         """
[1;32m    403[0m         [0;32mif[0m [0misinstance[0m[0;34m([0m[0mkey_or_keys[0m[0;34m,[0m [0m_KEY_TYPES[0m[0;34m)[0m[0;34m:[0m[0;34m[0m[0;34m[0m[0m
[0;32m--> 404[0;31m             [0;32mreturn[0m [0mself[0m[0;34m.[0m[0mget_vector[0m[0;34m([0m[0mkey_or_keys[0m[0;34m)[0m[0;34m[0m[0;34m[0m[0m
[0m[1;32m    405[0m [0;34m[0m[0m
[1;32m    406[0m         [0;32mreturn[0m [0mvstack[0m[0;34m([0m[0;34m[[0m[0mself[0m[0;34m.[0m[0mget_vector[0m[0;34m([0m[0mkey[0m[0;34m)[0m [0;32mfor[0m [0mkey[0m [0;32min[0m [0mkey_or_keys[0m[0;34m][0m[0;34m)[0m[0;34m[0m[0;34m[0m[0m

[0;32m~/opt/anaconda3/lib/python3.7/site-packages/gensim/models/keyedvectors.py[0m in [0;36mget_vector[0;34m(self, key, norm)[0m
[1;32m    445[0m [0;34m[0m[0m
[1;32m    446[0m         """
[0;32m--> 447[0;31m         [0mindex[0m [0;34m=[0m [0mself[0m[0;34m.[0m[0mget_index[0m[0;34m([0m[0mkey[0m[0;34m)[0m[0;34m[0m[0;34m[0m[0m
[0m[1;32m    448[0m         [0;32mif[0m [0mnorm[0m[0;34m:[0m[0;34m[0m[0;34m[0m[0m
[1;32m    449[0m             [0mself[0m[0;34m.[0m[0mfill_norms[0m[0;34m([0m[0;34m)[0m[0;34m[0m[0;34m[0m[0m

[0;32m~/opt/anaconda3/lib/python3.7/site-packages/gensim/models/keyedvectors.py[0m in [0;36mget_index[0;34m(self, key, default)[0m
[1;32m    419[0m             [0;32mreturn[0m [0mdefault[0m[0;34m[0m[0;34m[0m[0m
[1;32m    420[0m         [0;32melse[0m[0;34m:[0m[0;34m[0m[0;34m[0m[0m
[0;32m--> 421[0;31m             [0;32mraise[0m [0mKeyError[0m[0;34m([0m[0;34mf"Key '{key}' not present"[0m[0;34m)[0m[0;34m[0m[0;34m[0m[0m
[0m[1;32m    422[0m [0;34m[0m[0m
[1;32m    423[0m     [0;32mdef[0m [0mget_vector[0m[0;34m([0m[0mself[0m[0;34m,[0m [0mkey[0m[0;34m,[0m [0mnorm[0m[0;34m=[0m[0;32mFalse[0m[0;34m)[0m[0;34m:[0m[0;34m[0m[0;34m[0m[0m

[0;31mKeyError[0m: "Key 'man' not present"
KeyError: "Key 'man' not present"

